[2022-06-06 11:09:46,083] {taskinstance.py:1159} INFO - Dependencies all met for <TaskInstance: hands_on_test.drop_order_detail_table scheduled__2022-06-05T00:00:00+00:00 [queued]>
[2022-06-06 11:09:46,097] {taskinstance.py:1159} INFO - Dependencies all met for <TaskInstance: hands_on_test.drop_order_detail_table scheduled__2022-06-05T00:00:00+00:00 [queued]>
[2022-06-06 11:09:46,098] {taskinstance.py:1356} INFO - 
--------------------------------------------------------------------------------
[2022-06-06 11:09:46,099] {taskinstance.py:1357} INFO - Starting attempt 2 of 2
[2022-06-06 11:09:46,100] {taskinstance.py:1358} INFO - 
--------------------------------------------------------------------------------
[2022-06-06 11:09:46,119] {taskinstance.py:1377} INFO - Executing <Task(PostgresOperator): drop_order_detail_table> on 2022-06-05 00:00:00+00:00
[2022-06-06 11:09:46,127] {standard_task_runner.py:52} INFO - Started process 679 to run task
[2022-06-06 11:09:46,134] {standard_task_runner.py:79} INFO - Running: ['***', 'tasks', 'run', 'hands_on_test', 'drop_order_detail_table', 'scheduled__2022-06-05T00:00:00+00:00', '--job-id', '11', '--raw', '--subdir', 'DAGS_FOLDER/dag.py', '--cfg-path', '/tmp/tmprcvfvxo2', '--error-file', '/tmp/tmpidfb7_mc']
[2022-06-06 11:09:46,137] {standard_task_runner.py:80} INFO - Job 11: Subtask drop_order_detail_table
[2022-06-06 11:09:46,224] {task_command.py:369} INFO - Running <TaskInstance: hands_on_test.drop_order_detail_table scheduled__2022-06-05T00:00:00+00:00 [running]> on host 0c241499c9fe
[2022-06-06 11:09:46,325] {taskinstance.py:1571} INFO - Exporting the following env vars:
AIRFLOW_CTX_DAG_OWNER=pathairs
AIRFLOW_CTX_DAG_ID=hands_on_test
AIRFLOW_CTX_TASK_ID=drop_order_detail_table
AIRFLOW_CTX_EXECUTION_DATE=2022-06-05T00:00:00+00:00
AIRFLOW_CTX_TRY_NUMBER=2
AIRFLOW_CTX_DAG_RUN_ID=scheduled__2022-06-05T00:00:00+00:00
[2022-06-06 11:09:46,355] {taskinstance.py:1889} ERROR - Task failed with exception
Traceback (most recent call last):
  File "/home/airflow/.local/lib/python3.7/site-packages/airflow/providers/postgres/operators/postgres.py", line 92, in execute
    self.hook.run(self.sql, self.autocommit, parameters=self.parameters)
  File "/home/airflow/.local/lib/python3.7/site-packages/airflow/hooks/dbapi.py", line 181, in run
    with closing(self.get_conn()) as conn:
  File "/home/airflow/.local/lib/python3.7/site-packages/airflow/providers/postgres/hooks/postgres.py", line 86, in get_conn
    conn = deepcopy(self.connection or self.get_connection(conn_id))
  File "/home/airflow/.local/lib/python3.7/site-packages/airflow/hooks/base.py", line 67, in get_connection
    conn = Connection.get_connection_from_secrets(conn_id)
  File "/home/airflow/.local/lib/python3.7/site-packages/airflow/models/connection.py", line 430, in get_connection_from_secrets
    raise AirflowNotFoundException(f"The conn_id `{conn_id}` isn't defined")
airflow.exceptions.AirflowNotFoundException: The conn_id `postgres_db` isn't defined
[2022-06-06 11:09:46,363] {taskinstance.py:1400} INFO - Marking task as FAILED. dag_id=hands_on_test, task_id=drop_order_detail_table, execution_date=20220605T000000, start_date=20220606T110946, end_date=20220606T110946
[2022-06-06 11:09:46,552] {standard_task_runner.py:97} ERROR - Failed to execute job 11 for task drop_order_detail_table (The conn_id `postgres_db` isn't defined; 679)
[2022-06-06 11:09:46,592] {local_task_job.py:156} INFO - Task exited with return code 1
[2022-06-06 11:09:46,791] {local_task_job.py:273} INFO - 0 downstream tasks scheduled from follow-on schedule check
