[2022-06-07 04:56:04,407] {taskinstance.py:1159} INFO - Dependencies all met for <TaskInstance: hands_on_test.import_sqoop scheduled__2022-06-06T00:00:00+00:00 [queued]>
[2022-06-07 04:56:04,426] {taskinstance.py:1159} INFO - Dependencies all met for <TaskInstance: hands_on_test.import_sqoop scheduled__2022-06-06T00:00:00+00:00 [queued]>
[2022-06-07 04:56:04,427] {taskinstance.py:1356} INFO - 
--------------------------------------------------------------------------------
[2022-06-07 04:56:04,428] {taskinstance.py:1357} INFO - Starting attempt 5 of 6
[2022-06-07 04:56:04,429] {taskinstance.py:1358} INFO - 
--------------------------------------------------------------------------------
[2022-06-07 04:56:04,449] {taskinstance.py:1377} INFO - Executing <Task(BashOperator): import_sqoop> on 2022-06-06 00:00:00+00:00
[2022-06-07 04:56:04,455] {standard_task_runner.py:52} INFO - Started process 1464 to run task
[2022-06-07 04:56:04,460] {standard_task_runner.py:79} INFO - Running: ['***', 'tasks', 'run', 'hands_on_test', 'import_sqoop', 'scheduled__2022-06-06T00:00:00+00:00', '--job-id', '35', '--raw', '--subdir', 'DAGS_FOLDER/dag.py', '--cfg-path', '/tmp/tmprkjzyw9c', '--error-file', '/tmp/tmp7n99z_ww']
[2022-06-07 04:56:04,463] {standard_task_runner.py:80} INFO - Job 35: Subtask import_sqoop
[2022-06-07 04:56:04,541] {task_command.py:369} INFO - Running <TaskInstance: hands_on_test.import_sqoop scheduled__2022-06-06T00:00:00+00:00 [running]> on host a4a1e1d603db
[2022-06-07 04:56:04,664] {taskinstance.py:1571} INFO - Exporting the following env vars:
AIRFLOW_CTX_DAG_OWNER=pathairs
AIRFLOW_CTX_DAG_ID=hands_on_test
AIRFLOW_CTX_TASK_ID=import_sqoop
AIRFLOW_CTX_EXECUTION_DATE=2022-06-06T00:00:00+00:00
AIRFLOW_CTX_TRY_NUMBER=5
AIRFLOW_CTX_DAG_RUN_ID=scheduled__2022-06-06T00:00:00+00:00
[2022-06-07 04:56:04,666] {subprocess.py:62} INFO - Tmp dir root location: 
 /tmp
[2022-06-07 04:56:04,668] {subprocess.py:74} INFO - Running command: ['bash', '-c', 'docker exec hive-server bash /opt/sqoop/import_sqoop.sh ']
[2022-06-07 04:56:04,683] {subprocess.py:85} INFO - Output:
[2022-06-07 04:56:07,013] {subprocess.py:92} INFO - 22/06/07 04:56:07 INFO fs.TrashPolicyDefault: Namenode trash configuration: Deletion interval = 0 minutes, Emptier interval = 0 minutes.
[2022-06-07 04:56:07,021] {subprocess.py:92} INFO - Deleted /user/sqoop
[2022-06-07 04:56:09,410] {subprocess.py:92} INFO - Warning: /usr/lib/sqoop/bin/../../hbase does not exist! HBase imports will fail.
[2022-06-07 04:56:09,411] {subprocess.py:92} INFO - Please set $HBASE_HOME to the root of your HBase installation.
[2022-06-07 04:56:09,412] {subprocess.py:92} INFO - Warning: /usr/lib/sqoop/bin/../../hcatalog does not exist! HCatalog jobs will fail.
[2022-06-07 04:56:09,413] {subprocess.py:92} INFO - Please set $HCAT_HOME to the root of your HCatalog installation.
[2022-06-07 04:56:09,414] {subprocess.py:92} INFO - Warning: /usr/lib/sqoop/bin/../../accumulo does not exist! Accumulo imports will fail.
[2022-06-07 04:56:09,415] {subprocess.py:92} INFO - Please set $ACCUMULO_HOME to the root of your Accumulo installation.
[2022-06-07 04:56:09,415] {subprocess.py:92} INFO - Warning: /usr/lib/sqoop/bin/../../zookeeper does not exist! Accumulo imports will fail.
[2022-06-07 04:56:09,416] {subprocess.py:92} INFO - Please set $ZOOKEEPER_HOME to the root of your Zookeeper installation.
[2022-06-07 04:56:09,989] {subprocess.py:92} INFO - 22/06/07 04:56:09 INFO sqoop.Sqoop: Running Sqoop version: 1.4.7
[2022-06-07 04:56:10,078] {subprocess.py:92} INFO - 22/06/07 04:56:10 WARN tool.BaseSqoopTool: Setting your password on the command-line is insecure. Consider using -P instead.
[2022-06-07 04:56:10,082] {subprocess.py:92} INFO - 22/06/07 04:56:10 WARN tool.BaseSqoopTool: It seems that you've specified at least one of following:
[2022-06-07 04:56:10,084] {subprocess.py:92} INFO - 22/06/07 04:56:10 WARN tool.BaseSqoopTool: 	--hive-home
[2022-06-07 04:56:10,085] {subprocess.py:92} INFO - 22/06/07 04:56:10 WARN tool.BaseSqoopTool: 	--hive-overwrite
[2022-06-07 04:56:10,086] {subprocess.py:92} INFO - 22/06/07 04:56:10 WARN tool.BaseSqoopTool: 	--create-hive-table
[2022-06-07 04:56:10,086] {subprocess.py:92} INFO - 22/06/07 04:56:10 WARN tool.BaseSqoopTool: 	--hive-table
[2022-06-07 04:56:10,087] {subprocess.py:92} INFO - 22/06/07 04:56:10 WARN tool.BaseSqoopTool: 	--hive-partition-key
[2022-06-07 04:56:10,087] {subprocess.py:92} INFO - 22/06/07 04:56:10 WARN tool.BaseSqoopTool: 	--hive-partition-value
[2022-06-07 04:56:10,088] {subprocess.py:92} INFO - 22/06/07 04:56:10 WARN tool.BaseSqoopTool: 	--map-column-hive
[2022-06-07 04:56:10,088] {subprocess.py:92} INFO - 22/06/07 04:56:10 WARN tool.BaseSqoopTool: Without specifying parameter --hive-import. Please note that
[2022-06-07 04:56:10,089] {subprocess.py:92} INFO - 22/06/07 04:56:10 WARN tool.BaseSqoopTool: those arguments will not be used in this session. Either
[2022-06-07 04:56:10,090] {subprocess.py:92} INFO - 22/06/07 04:56:10 WARN tool.BaseSqoopTool: specify --hive-import to apply them correctly or remove them
[2022-06-07 04:56:10,090] {subprocess.py:92} INFO - 22/06/07 04:56:10 WARN tool.BaseSqoopTool: from command line to remove this warning.
[2022-06-07 04:56:10,091] {subprocess.py:92} INFO - 22/06/07 04:56:10 INFO tool.BaseSqoopTool: Please note that --hive-home, --hive-partition-key,
[2022-06-07 04:56:10,092] {subprocess.py:92} INFO - 22/06/07 04:56:10 INFO tool.BaseSqoopTool: 	 hive-partition-value and --map-column-hive options are
[2022-06-07 04:56:10,093] {subprocess.py:92} INFO - 22/06/07 04:56:10 INFO tool.BaseSqoopTool: 	 are also valid for HCatalog imports and exports
[2022-06-07 04:56:10,190] {subprocess.py:92} INFO - 22/06/07 04:56:10 INFO manager.SqlManager: Using default fetchSize of 1000
[2022-06-07 04:56:10,191] {subprocess.py:92} INFO - 22/06/07 04:56:10 INFO tool.CodeGenTool: Beginning code generation
[2022-06-07 04:56:10,262] {subprocess.py:92} INFO - 22/06/07 04:56:10 ERROR manager.SqlManager: Error executing statement: org.postgresql.util.PSQLException: The connection attempt failed.
[2022-06-07 04:56:10,263] {subprocess.py:92} INFO - org.postgresql.util.PSQLException: The connection attempt failed.
[2022-06-07 04:56:10,264] {subprocess.py:92} INFO - 	at org.postgresql.core.v3.ConnectionFactoryImpl.openConnectionImpl(ConnectionFactoryImpl.java:315)
[2022-06-07 04:56:10,264] {subprocess.py:92} INFO - 	at org.postgresql.core.ConnectionFactory.openConnection(ConnectionFactory.java:51)
[2022-06-07 04:56:10,265] {subprocess.py:92} INFO - 	at org.postgresql.jdbc.PgConnection.<init>(PgConnection.java:223)
[2022-06-07 04:56:10,266] {subprocess.py:92} INFO - 	at org.postgresql.Driver.makeConnection(Driver.java:465)
[2022-06-07 04:56:10,267] {subprocess.py:92} INFO - 	at org.postgresql.Driver.connect(Driver.java:264)
[2022-06-07 04:56:10,268] {subprocess.py:92} INFO - 	at java.sql.DriverManager.getConnection(DriverManager.java:664)
[2022-06-07 04:56:10,268] {subprocess.py:92} INFO - 	at java.sql.DriverManager.getConnection(DriverManager.java:247)
[2022-06-07 04:56:10,274] {subprocess.py:92} INFO - 	at org.apache.sqoop.manager.SqlManager.makeConnection(SqlManager.java:904)
[2022-06-07 04:56:10,274] {subprocess.py:92} INFO - 	at org.apache.sqoop.manager.GenericJdbcManager.getConnection(GenericJdbcManager.java:59)
[2022-06-07 04:56:10,275] {subprocess.py:92} INFO - 	at org.apache.sqoop.manager.SqlManager.execute(SqlManager.java:763)
[2022-06-07 04:56:10,279] {subprocess.py:92} INFO - 	at org.apache.sqoop.manager.SqlManager.execute(SqlManager.java:786)
[2022-06-07 04:56:10,280] {subprocess.py:92} INFO - 	at org.apache.sqoop.manager.SqlManager.getColumnInfoForRawQuery(SqlManager.java:289)
[2022-06-07 04:56:10,281] {subprocess.py:92} INFO - 	at org.apache.sqoop.manager.SqlManager.getColumnTypesForRawQuery(SqlManager.java:260)
[2022-06-07 04:56:10,281] {subprocess.py:92} INFO - 	at org.apache.sqoop.manager.SqlManager.getColumnTypes(SqlManager.java:246)
[2022-06-07 04:56:10,282] {subprocess.py:92} INFO - 	at org.apache.sqoop.manager.ConnManager.getColumnTypes(ConnManager.java:327)
[2022-06-07 04:56:10,282] {subprocess.py:92} INFO - 	at org.apache.sqoop.orm.ClassWriter.getColumnTypes(ClassWriter.java:1872)
[2022-06-07 04:56:10,284] {subprocess.py:92} INFO - 	at org.apache.sqoop.orm.ClassWriter.generate(ClassWriter.java:1671)
[2022-06-07 04:56:10,284] {subprocess.py:92} INFO - 	at org.apache.sqoop.tool.CodeGenTool.generateORM(CodeGenTool.java:106)
[2022-06-07 04:56:10,285] {subprocess.py:92} INFO - 	at org.apache.sqoop.tool.ImportTool.importTable(ImportTool.java:501)
[2022-06-07 04:56:10,286] {subprocess.py:92} INFO - 	at org.apache.sqoop.tool.ImportTool.run(ImportTool.java:628)
[2022-06-07 04:56:10,287] {subprocess.py:92} INFO - 	at org.apache.sqoop.Sqoop.run(Sqoop.java:147)
[2022-06-07 04:56:10,288] {subprocess.py:92} INFO - 	at org.apache.hadoop.util.ToolRunner.run(ToolRunner.java:70)
[2022-06-07 04:56:10,289] {subprocess.py:92} INFO - 	at org.apache.sqoop.Sqoop.runSqoop(Sqoop.java:183)
[2022-06-07 04:56:10,290] {subprocess.py:92} INFO - 	at org.apache.sqoop.Sqoop.runTool(Sqoop.java:234)
[2022-06-07 04:56:10,290] {subprocess.py:92} INFO - 	at org.apache.sqoop.Sqoop.runTool(Sqoop.java:243)
[2022-06-07 04:56:10,291] {subprocess.py:92} INFO - 	at org.apache.sqoop.Sqoop.main(Sqoop.java:252)
[2022-06-07 04:56:10,292] {subprocess.py:92} INFO - Caused by: java.net.UnknownHostException: database
[2022-06-07 04:56:10,293] {subprocess.py:92} INFO - 	at java.net.AbstractPlainSocketImpl.connect(AbstractPlainSocketImpl.java:184)
[2022-06-07 04:56:10,293] {subprocess.py:92} INFO - 	at java.net.SocksSocketImpl.connect(SocksSocketImpl.java:392)
[2022-06-07 04:56:10,294] {subprocess.py:92} INFO - 	at java.net.Socket.connect(Socket.java:589)
[2022-06-07 04:56:10,294] {subprocess.py:92} INFO - 	at org.postgresql.core.PGStream.createSocket(PGStream.java:231)
[2022-06-07 04:56:10,295] {subprocess.py:92} INFO - 	at org.postgresql.core.PGStream.<init>(PGStream.java:95)
[2022-06-07 04:56:10,296] {subprocess.py:92} INFO - 	at org.postgresql.core.v3.ConnectionFactoryImpl.tryConnect(ConnectionFactoryImpl.java:98)
[2022-06-07 04:56:10,296] {subprocess.py:92} INFO - 	at org.postgresql.core.v3.ConnectionFactoryImpl.openConnectionImpl(ConnectionFactoryImpl.java:213)
[2022-06-07 04:56:10,297] {subprocess.py:92} INFO - 	... 25 more
[2022-06-07 04:56:10,298] {subprocess.py:92} INFO - 22/06/07 04:56:10 ERROR tool.ImportTool: Import failed: java.io.IOException: No columns to generate for ClassWriter
[2022-06-07 04:56:10,298] {subprocess.py:92} INFO - 	at org.apache.sqoop.orm.ClassWriter.generate(ClassWriter.java:1677)
[2022-06-07 04:56:10,299] {subprocess.py:92} INFO - 	at org.apache.sqoop.tool.CodeGenTool.generateORM(CodeGenTool.java:106)
[2022-06-07 04:56:10,299] {subprocess.py:92} INFO - 	at org.apache.sqoop.tool.ImportTool.importTable(ImportTool.java:501)
[2022-06-07 04:56:10,300] {subprocess.py:92} INFO - 	at org.apache.sqoop.tool.ImportTool.run(ImportTool.java:628)
[2022-06-07 04:56:10,301] {subprocess.py:92} INFO - 	at org.apache.sqoop.Sqoop.run(Sqoop.java:147)
[2022-06-07 04:56:10,301] {subprocess.py:92} INFO - 	at org.apache.hadoop.util.ToolRunner.run(ToolRunner.java:70)
[2022-06-07 04:56:10,302] {subprocess.py:92} INFO - 	at org.apache.sqoop.Sqoop.runSqoop(Sqoop.java:183)
[2022-06-07 04:56:10,303] {subprocess.py:92} INFO - 	at org.apache.sqoop.Sqoop.runTool(Sqoop.java:234)
[2022-06-07 04:56:10,303] {subprocess.py:92} INFO - 	at org.apache.sqoop.Sqoop.runTool(Sqoop.java:243)
[2022-06-07 04:56:10,304] {subprocess.py:92} INFO - 	at org.apache.sqoop.Sqoop.main(Sqoop.java:252)
[2022-06-07 04:56:10,305] {subprocess.py:92} INFO - 
[2022-06-07 04:56:10,306] {subprocess.py:92} INFO - Warning: /usr/lib/sqoop/bin/../../hbase does not exist! HBase imports will fail.
[2022-06-07 04:56:10,307] {subprocess.py:92} INFO - Please set $HBASE_HOME to the root of your HBase installation.
[2022-06-07 04:56:10,307] {subprocess.py:92} INFO - Warning: /usr/lib/sqoop/bin/../../hcatalog does not exist! HCatalog jobs will fail.
[2022-06-07 04:56:10,308] {subprocess.py:92} INFO - Please set $HCAT_HOME to the root of your HCatalog installation.
[2022-06-07 04:56:10,308] {subprocess.py:92} INFO - Warning: /usr/lib/sqoop/bin/../../accumulo does not exist! Accumulo imports will fail.
[2022-06-07 04:56:10,309] {subprocess.py:92} INFO - Please set $ACCUMULO_HOME to the root of your Accumulo installation.
[2022-06-07 04:56:10,310] {subprocess.py:92} INFO - Warning: /usr/lib/sqoop/bin/../../zookeeper does not exist! Accumulo imports will fail.
[2022-06-07 04:56:10,311] {subprocess.py:92} INFO - Please set $ZOOKEEPER_HOME to the root of your Zookeeper installation.
[2022-06-07 04:56:10,879] {subprocess.py:92} INFO - 22/06/07 04:56:10 INFO sqoop.Sqoop: Running Sqoop version: 1.4.7
[2022-06-07 04:56:10,960] {subprocess.py:92} INFO - 22/06/07 04:56:10 WARN tool.BaseSqoopTool: Setting your password on the command-line is insecure. Consider using -P instead.
[2022-06-07 04:56:11,058] {subprocess.py:92} INFO - 22/06/07 04:56:11 INFO manager.SqlManager: Using default fetchSize of 1000
[2022-06-07 04:56:11,060] {subprocess.py:92} INFO - 22/06/07 04:56:11 INFO tool.CodeGenTool: Beginning code generation
[2022-06-07 04:56:11,132] {subprocess.py:92} INFO - 22/06/07 04:56:11 ERROR manager.SqlManager: Error executing statement: org.postgresql.util.PSQLException: The connection attempt failed.
[2022-06-07 04:56:11,133] {subprocess.py:92} INFO - org.postgresql.util.PSQLException: The connection attempt failed.
[2022-06-07 04:56:11,134] {subprocess.py:92} INFO - 	at org.postgresql.core.v3.ConnectionFactoryImpl.openConnectionImpl(ConnectionFactoryImpl.java:315)
[2022-06-07 04:56:11,134] {subprocess.py:92} INFO - 	at org.postgresql.core.ConnectionFactory.openConnection(ConnectionFactory.java:51)
[2022-06-07 04:56:11,135] {subprocess.py:92} INFO - 	at org.postgresql.jdbc.PgConnection.<init>(PgConnection.java:223)
[2022-06-07 04:56:11,136] {subprocess.py:92} INFO - 	at org.postgresql.Driver.makeConnection(Driver.java:465)
[2022-06-07 04:56:11,139] {subprocess.py:92} INFO - 	at org.postgresql.Driver.connect(Driver.java:264)
[2022-06-07 04:56:11,140] {subprocess.py:92} INFO - 	at java.sql.DriverManager.getConnection(DriverManager.java:664)
[2022-06-07 04:56:11,141] {subprocess.py:92} INFO - 	at java.sql.DriverManager.getConnection(DriverManager.java:247)
[2022-06-07 04:56:11,142] {subprocess.py:92} INFO - 	at org.apache.sqoop.manager.SqlManager.makeConnection(SqlManager.java:904)
[2022-06-07 04:56:11,143] {subprocess.py:92} INFO - 	at org.apache.sqoop.manager.GenericJdbcManager.getConnection(GenericJdbcManager.java:59)
[2022-06-07 04:56:11,144] {subprocess.py:92} INFO - 	at org.apache.sqoop.manager.SqlManager.execute(SqlManager.java:763)
[2022-06-07 04:56:11,145] {subprocess.py:92} INFO - 	at org.apache.sqoop.manager.SqlManager.execute(SqlManager.java:786)
[2022-06-07 04:56:11,146] {subprocess.py:92} INFO - 	at org.apache.sqoop.manager.SqlManager.getColumnInfoForRawQuery(SqlManager.java:289)
[2022-06-07 04:56:11,147] {subprocess.py:92} INFO - 	at org.apache.sqoop.manager.SqlManager.getColumnTypesForRawQuery(SqlManager.java:260)
[2022-06-07 04:56:11,148] {subprocess.py:92} INFO - 	at org.apache.sqoop.manager.SqlManager.getColumnTypes(SqlManager.java:246)
[2022-06-07 04:56:11,149] {subprocess.py:92} INFO - 	at org.apache.sqoop.manager.ConnManager.getColumnTypes(ConnManager.java:327)
[2022-06-07 04:56:11,150] {subprocess.py:92} INFO - 	at org.apache.sqoop.orm.ClassWriter.getColumnTypes(ClassWriter.java:1872)
[2022-06-07 04:56:11,151] {subprocess.py:92} INFO - 	at org.apache.sqoop.orm.ClassWriter.generate(ClassWriter.java:1671)
[2022-06-07 04:56:11,152] {subprocess.py:92} INFO - 	at org.apache.sqoop.tool.CodeGenTool.generateORM(CodeGenTool.java:106)
[2022-06-07 04:56:11,155] {subprocess.py:92} INFO - 	at org.apache.sqoop.tool.ImportTool.importTable(ImportTool.java:501)
[2022-06-07 04:56:11,156] {subprocess.py:92} INFO - 	at org.apache.sqoop.tool.ImportTool.run(ImportTool.java:628)
[2022-06-07 04:56:11,157] {subprocess.py:92} INFO - 	at org.apache.sqoop.Sqoop.run(Sqoop.java:147)
[2022-06-07 04:56:11,159] {subprocess.py:92} INFO - 	at org.apache.hadoop.util.ToolRunner.run(ToolRunner.java:70)
[2022-06-07 04:56:11,160] {subprocess.py:92} INFO - 	at org.apache.sqoop.Sqoop.runSqoop(Sqoop.java:183)
[2022-06-07 04:56:11,162] {subprocess.py:92} INFO - 	at org.apache.sqoop.Sqoop.runTool(Sqoop.java:234)
[2022-06-07 04:56:11,163] {subprocess.py:92} INFO - 	at org.apache.sqoop.Sqoop.runTool(Sqoop.java:243)
[2022-06-07 04:56:11,164] {subprocess.py:92} INFO - 	at org.apache.sqoop.Sqoop.main(Sqoop.java:252)
[2022-06-07 04:56:11,165] {subprocess.py:92} INFO - Caused by: java.net.UnknownHostException: database
[2022-06-07 04:56:11,165] {subprocess.py:92} INFO - 	at java.net.AbstractPlainSocketImpl.connect(AbstractPlainSocketImpl.java:184)
[2022-06-07 04:56:11,166] {subprocess.py:92} INFO - 	at java.net.SocksSocketImpl.connect(SocksSocketImpl.java:392)
[2022-06-07 04:56:11,167] {subprocess.py:92} INFO - 	at java.net.Socket.connect(Socket.java:589)
[2022-06-07 04:56:11,167] {subprocess.py:92} INFO - 	at org.postgresql.core.PGStream.createSocket(PGStream.java:231)
[2022-06-07 04:56:11,168] {subprocess.py:92} INFO - 	at org.postgresql.core.PGStream.<init>(PGStream.java:95)
[2022-06-07 04:56:11,169] {subprocess.py:92} INFO - 	at org.postgresql.core.v3.ConnectionFactoryImpl.tryConnect(ConnectionFactoryImpl.java:98)
[2022-06-07 04:56:11,169] {subprocess.py:92} INFO - 	at org.postgresql.core.v3.ConnectionFactoryImpl.openConnectionImpl(ConnectionFactoryImpl.java:213)
[2022-06-07 04:56:11,170] {subprocess.py:92} INFO - 	... 25 more
[2022-06-07 04:56:11,171] {subprocess.py:92} INFO - 22/06/07 04:56:11 ERROR tool.ImportTool: Import failed: java.io.IOException: No columns to generate for ClassWriter
[2022-06-07 04:56:11,171] {subprocess.py:92} INFO - 	at org.apache.sqoop.orm.ClassWriter.generate(ClassWriter.java:1677)
[2022-06-07 04:56:11,172] {subprocess.py:92} INFO - 	at org.apache.sqoop.tool.CodeGenTool.generateORM(CodeGenTool.java:106)
[2022-06-07 04:56:11,173] {subprocess.py:92} INFO - 	at org.apache.sqoop.tool.ImportTool.importTable(ImportTool.java:501)
[2022-06-07 04:56:11,173] {subprocess.py:92} INFO - 	at org.apache.sqoop.tool.ImportTool.run(ImportTool.java:628)
[2022-06-07 04:56:11,174] {subprocess.py:92} INFO - 	at org.apache.sqoop.Sqoop.run(Sqoop.java:147)
[2022-06-07 04:56:11,175] {subprocess.py:92} INFO - 	at org.apache.hadoop.util.ToolRunner.run(ToolRunner.java:70)
[2022-06-07 04:56:11,176] {subprocess.py:92} INFO - 	at org.apache.sqoop.Sqoop.runSqoop(Sqoop.java:183)
[2022-06-07 04:56:11,177] {subprocess.py:92} INFO - 	at org.apache.sqoop.Sqoop.runTool(Sqoop.java:234)
[2022-06-07 04:56:11,177] {subprocess.py:92} INFO - 	at org.apache.sqoop.Sqoop.runTool(Sqoop.java:243)
[2022-06-07 04:56:11,178] {subprocess.py:92} INFO - 	at org.apache.sqoop.Sqoop.main(Sqoop.java:252)
[2022-06-07 04:56:11,179] {subprocess.py:92} INFO - 
[2022-06-07 04:56:11,180] {subprocess.py:96} INFO - Command exited with return code 1
[2022-06-07 04:56:11,201] {taskinstance.py:1889} ERROR - Task failed with exception
Traceback (most recent call last):
  File "/home/airflow/.local/lib/python3.7/site-packages/airflow/operators/bash.py", line 195, in execute
    f'Bash command failed. The command returned a non-zero exit code {result.exit_code}.'
airflow.exceptions.AirflowException: Bash command failed. The command returned a non-zero exit code 1.
[2022-06-07 04:56:11,207] {taskinstance.py:1400} INFO - Marking task as UP_FOR_RETRY. dag_id=hands_on_test, task_id=import_sqoop, execution_date=20220606T000000, start_date=20220607T045604, end_date=20220607T045611
[2022-06-07 04:56:11,223] {standard_task_runner.py:97} ERROR - Failed to execute job 35 for task import_sqoop (Bash command failed. The command returned a non-zero exit code 1.; 1464)
[2022-06-07 04:56:11,270] {local_task_job.py:156} INFO - Task exited with return code 1
[2022-06-07 04:56:11,339] {local_task_job.py:273} INFO - 0 downstream tasks scheduled from follow-on schedule check
