[2022-06-07 06:11:18,840] {taskinstance.py:1159} INFO - Dependencies all met for <TaskInstance: hands_on_test.import_sqoop scheduled__2022-06-06T00:00:00+00:00 [queued]>
[2022-06-07 06:11:18,860] {taskinstance.py:1159} INFO - Dependencies all met for <TaskInstance: hands_on_test.import_sqoop scheduled__2022-06-06T00:00:00+00:00 [queued]>
[2022-06-07 06:11:18,861] {taskinstance.py:1356} INFO - 
--------------------------------------------------------------------------------
[2022-06-07 06:11:18,862] {taskinstance.py:1357} INFO - Starting attempt 7 of 8
[2022-06-07 06:11:18,863] {taskinstance.py:1358} INFO - 
--------------------------------------------------------------------------------
[2022-06-07 06:11:18,883] {taskinstance.py:1377} INFO - Executing <Task(BashOperator): import_sqoop> on 2022-06-06 00:00:00+00:00
[2022-06-07 06:11:18,891] {standard_task_runner.py:52} INFO - Started process 6036 to run task
[2022-06-07 06:11:18,897] {standard_task_runner.py:79} INFO - Running: ['***', 'tasks', 'run', 'hands_on_test', 'import_sqoop', 'scheduled__2022-06-06T00:00:00+00:00', '--job-id', '37', '--raw', '--subdir', 'DAGS_FOLDER/dag.py', '--cfg-path', '/tmp/tmpsb95l3xr', '--error-file', '/tmp/tmptndb4els']
[2022-06-07 06:11:18,899] {standard_task_runner.py:80} INFO - Job 37: Subtask import_sqoop
[2022-06-07 06:11:18,974] {task_command.py:369} INFO - Running <TaskInstance: hands_on_test.import_sqoop scheduled__2022-06-06T00:00:00+00:00 [running]> on host a4a1e1d603db
[2022-06-07 06:11:19,069] {taskinstance.py:1571} INFO - Exporting the following env vars:
AIRFLOW_CTX_DAG_OWNER=pathairs
AIRFLOW_CTX_DAG_ID=hands_on_test
AIRFLOW_CTX_TASK_ID=import_sqoop
AIRFLOW_CTX_EXECUTION_DATE=2022-06-06T00:00:00+00:00
AIRFLOW_CTX_TRY_NUMBER=7
AIRFLOW_CTX_DAG_RUN_ID=scheduled__2022-06-06T00:00:00+00:00
[2022-06-07 06:11:19,072] {subprocess.py:62} INFO - Tmp dir root location: 
 /tmp
[2022-06-07 06:11:19,073] {subprocess.py:74} INFO - Running command: ['bash', '-c', 'docker exec hive-server bash /opt/sqoop/import_sqoop.sh ']
[2022-06-07 06:11:19,087] {subprocess.py:85} INFO - Output:
[2022-06-07 06:11:20,814] {subprocess.py:92} INFO - 22/06/07 06:11:20 INFO fs.TrashPolicyDefault: Namenode trash configuration: Deletion interval = 0 minutes, Emptier interval = 0 minutes.
[2022-06-07 06:11:20,824] {subprocess.py:92} INFO - Deleted /user/sqoop
[2022-06-07 06:11:23,365] {subprocess.py:92} INFO - Warning: /usr/lib/sqoop/bin/../../hbase does not exist! HBase imports will fail.
[2022-06-07 06:11:23,366] {subprocess.py:92} INFO - Please set $HBASE_HOME to the root of your HBase installation.
[2022-06-07 06:11:23,367] {subprocess.py:92} INFO - Warning: /usr/lib/sqoop/bin/../../hcatalog does not exist! HCatalog jobs will fail.
[2022-06-07 06:11:23,367] {subprocess.py:92} INFO - Please set $HCAT_HOME to the root of your HCatalog installation.
[2022-06-07 06:11:23,368] {subprocess.py:92} INFO - Warning: /usr/lib/sqoop/bin/../../accumulo does not exist! Accumulo imports will fail.
[2022-06-07 06:11:23,369] {subprocess.py:92} INFO - Please set $ACCUMULO_HOME to the root of your Accumulo installation.
[2022-06-07 06:11:23,370] {subprocess.py:92} INFO - Warning: /usr/lib/sqoop/bin/../../zookeeper does not exist! Accumulo imports will fail.
[2022-06-07 06:11:23,371] {subprocess.py:92} INFO - Please set $ZOOKEEPER_HOME to the root of your Zookeeper installation.
[2022-06-07 06:11:24,028] {subprocess.py:92} INFO - 22/06/07 06:11:24 INFO sqoop.Sqoop: Running Sqoop version: 1.4.7
[2022-06-07 06:11:24,112] {subprocess.py:92} INFO - 22/06/07 06:11:24 WARN tool.BaseSqoopTool: Setting your password on the command-line is insecure. Consider using -P instead.
[2022-06-07 06:11:24,116] {subprocess.py:92} INFO - 22/06/07 06:11:24 WARN tool.BaseSqoopTool: It seems that you've specified at least one of following:
[2022-06-07 06:11:24,118] {subprocess.py:92} INFO - 22/06/07 06:11:24 WARN tool.BaseSqoopTool: 	--hive-home
[2022-06-07 06:11:24,119] {subprocess.py:92} INFO - 22/06/07 06:11:24 WARN tool.BaseSqoopTool: 	--hive-overwrite
[2022-06-07 06:11:24,120] {subprocess.py:92} INFO - 22/06/07 06:11:24 WARN tool.BaseSqoopTool: 	--create-hive-table
[2022-06-07 06:11:24,121] {subprocess.py:92} INFO - 22/06/07 06:11:24 WARN tool.BaseSqoopTool: 	--hive-table
[2022-06-07 06:11:24,122] {subprocess.py:92} INFO - 22/06/07 06:11:24 WARN tool.BaseSqoopTool: 	--hive-partition-key
[2022-06-07 06:11:24,122] {subprocess.py:92} INFO - 22/06/07 06:11:24 WARN tool.BaseSqoopTool: 	--hive-partition-value
[2022-06-07 06:11:24,123] {subprocess.py:92} INFO - 22/06/07 06:11:24 WARN tool.BaseSqoopTool: 	--map-column-hive
[2022-06-07 06:11:24,124] {subprocess.py:92} INFO - 22/06/07 06:11:24 WARN tool.BaseSqoopTool: Without specifying parameter --hive-import. Please note that
[2022-06-07 06:11:24,124] {subprocess.py:92} INFO - 22/06/07 06:11:24 WARN tool.BaseSqoopTool: those arguments will not be used in this session. Either
[2022-06-07 06:11:24,125] {subprocess.py:92} INFO - 22/06/07 06:11:24 WARN tool.BaseSqoopTool: specify --hive-import to apply them correctly or remove them
[2022-06-07 06:11:24,126] {subprocess.py:92} INFO - 22/06/07 06:11:24 WARN tool.BaseSqoopTool: from command line to remove this warning.
[2022-06-07 06:11:24,127] {subprocess.py:92} INFO - 22/06/07 06:11:24 INFO tool.BaseSqoopTool: Please note that --hive-home, --hive-partition-key,
[2022-06-07 06:11:24,128] {subprocess.py:92} INFO - 22/06/07 06:11:24 INFO tool.BaseSqoopTool: 	 hive-partition-value and --map-column-hive options are
[2022-06-07 06:11:24,128] {subprocess.py:92} INFO - 22/06/07 06:11:24 INFO tool.BaseSqoopTool: 	 are also valid for HCatalog imports and exports
[2022-06-07 06:11:24,223] {subprocess.py:92} INFO - 22/06/07 06:11:24 INFO manager.SqlManager: Using default fetchSize of 1000
[2022-06-07 06:11:24,224] {subprocess.py:92} INFO - 22/06/07 06:11:24 INFO tool.CodeGenTool: Beginning code generation
[2022-06-07 06:11:24,418] {subprocess.py:92} INFO - 22/06/07 06:11:24 ERROR manager.SqlManager: Error executing statement: org.postgresql.util.PSQLException: The connection attempt failed.
[2022-06-07 06:11:24,420] {subprocess.py:92} INFO - org.postgresql.util.PSQLException: The connection attempt failed.
[2022-06-07 06:11:24,421] {subprocess.py:92} INFO - 	at org.postgresql.core.v3.ConnectionFactoryImpl.openConnectionImpl(ConnectionFactoryImpl.java:315)
[2022-06-07 06:11:24,422] {subprocess.py:92} INFO - 	at org.postgresql.core.ConnectionFactory.openConnection(ConnectionFactory.java:51)
[2022-06-07 06:11:24,422] {subprocess.py:92} INFO - 	at org.postgresql.jdbc.PgConnection.<init>(PgConnection.java:223)
[2022-06-07 06:11:24,423] {subprocess.py:92} INFO - 	at org.postgresql.Driver.makeConnection(Driver.java:465)
[2022-06-07 06:11:24,424] {subprocess.py:92} INFO - 	at org.postgresql.Driver.connect(Driver.java:264)
[2022-06-07 06:11:24,425] {subprocess.py:92} INFO - 	at java.sql.DriverManager.getConnection(DriverManager.java:664)
[2022-06-07 06:11:24,405] {subprocess.py:92} INFO - 	at java.sql.DriverManager.getConnection(DriverManager.java:247)
[2022-06-07 06:11:24,409] {subprocess.py:92} INFO - 	at org.apache.sqoop.manager.SqlManager.makeConnection(SqlManager.java:904)
[2022-06-07 06:11:24,410] {subprocess.py:92} INFO - 	at org.apache.sqoop.manager.GenericJdbcManager.getConnection(GenericJdbcManager.java:59)
[2022-06-07 06:11:24,411] {subprocess.py:92} INFO - 	at org.apache.sqoop.manager.SqlManager.execute(SqlManager.java:763)
[2022-06-07 06:11:24,413] {subprocess.py:92} INFO - 	at org.apache.sqoop.manager.SqlManager.execute(SqlManager.java:786)
[2022-06-07 06:11:24,414] {subprocess.py:92} INFO - 	at org.apache.sqoop.manager.SqlManager.getColumnInfoForRawQuery(SqlManager.java:289)
[2022-06-07 06:11:24,414] {subprocess.py:92} INFO - 	at org.apache.sqoop.manager.SqlManager.getColumnTypesForRawQuery(SqlManager.java:260)
[2022-06-07 06:11:24,417] {subprocess.py:92} INFO - 	at org.apache.sqoop.manager.SqlManager.getColumnTypes(SqlManager.java:246)
[2022-06-07 06:11:24,417] {subprocess.py:92} INFO - 	at org.apache.sqoop.manager.ConnManager.getColumnTypes(ConnManager.java:327)
[2022-06-07 06:11:24,418] {subprocess.py:92} INFO - 	at org.apache.sqoop.orm.ClassWriter.getColumnTypes(ClassWriter.java:1872)
[2022-06-07 06:11:24,420] {subprocess.py:92} INFO - 	at org.apache.sqoop.orm.ClassWriter.generate(ClassWriter.java:1671)
[2022-06-07 06:11:24,423] {subprocess.py:92} INFO - 	at org.apache.sqoop.tool.CodeGenTool.generateORM(CodeGenTool.java:106)
[2022-06-07 06:11:24,424] {subprocess.py:92} INFO - 	at org.apache.sqoop.tool.ImportTool.importTable(ImportTool.java:501)
[2022-06-07 06:11:24,424] {subprocess.py:92} INFO - 	at org.apache.sqoop.tool.ImportTool.run(ImportTool.java:628)
[2022-06-07 06:11:24,425] {subprocess.py:92} INFO - 	at org.apache.sqoop.Sqoop.run(Sqoop.java:147)
[2022-06-07 06:11:24,425] {subprocess.py:92} INFO - 	at org.apache.hadoop.util.ToolRunner.run(ToolRunner.java:70)
[2022-06-07 06:11:24,426] {subprocess.py:92} INFO - 	at org.apache.sqoop.Sqoop.runSqoop(Sqoop.java:183)
[2022-06-07 06:11:24,427] {subprocess.py:92} INFO - 	at org.apache.sqoop.Sqoop.runTool(Sqoop.java:234)
[2022-06-07 06:11:24,428] {subprocess.py:92} INFO - 	at org.apache.sqoop.Sqoop.runTool(Sqoop.java:243)
[2022-06-07 06:11:24,429] {subprocess.py:92} INFO - 	at org.apache.sqoop.Sqoop.main(Sqoop.java:252)
[2022-06-07 06:11:24,430] {subprocess.py:92} INFO - Caused by: java.net.UnknownHostException: ***
[2022-06-07 06:11:24,431] {subprocess.py:92} INFO - 	at java.net.AbstractPlainSocketImpl.connect(AbstractPlainSocketImpl.java:184)
[2022-06-07 06:11:24,432] {subprocess.py:92} INFO - 	at java.net.SocksSocketImpl.connect(SocksSocketImpl.java:392)
[2022-06-07 06:11:24,432] {subprocess.py:92} INFO - 	at java.net.Socket.connect(Socket.java:589)
[2022-06-07 06:11:24,433] {subprocess.py:92} INFO - 	at org.postgresql.core.PGStream.createSocket(PGStream.java:231)
[2022-06-07 06:11:24,434] {subprocess.py:92} INFO - 	at org.postgresql.core.PGStream.<init>(PGStream.java:95)
[2022-06-07 06:11:24,435] {subprocess.py:92} INFO - 	at org.postgresql.core.v3.ConnectionFactoryImpl.tryConnect(ConnectionFactoryImpl.java:98)
[2022-06-07 06:11:24,436] {subprocess.py:92} INFO - 	at org.postgresql.core.v3.ConnectionFactoryImpl.openConnectionImpl(ConnectionFactoryImpl.java:213)
[2022-06-07 06:11:24,436] {subprocess.py:92} INFO - 	... 25 more
[2022-06-07 06:11:24,437] {subprocess.py:92} INFO - 22/06/07 06:11:24 ERROR tool.ImportTool: Import failed: java.io.IOException: No columns to generate for ClassWriter
[2022-06-07 06:11:24,438] {subprocess.py:92} INFO - 	at org.apache.sqoop.orm.ClassWriter.generate(ClassWriter.java:1677)
[2022-06-07 06:11:24,439] {subprocess.py:92} INFO - 	at org.apache.sqoop.tool.CodeGenTool.generateORM(CodeGenTool.java:106)
[2022-06-07 06:11:24,439] {subprocess.py:92} INFO - 	at org.apache.sqoop.tool.ImportTool.importTable(ImportTool.java:501)
[2022-06-07 06:11:24,440] {subprocess.py:92} INFO - 	at org.apache.sqoop.tool.ImportTool.run(ImportTool.java:628)
[2022-06-07 06:11:24,441] {subprocess.py:92} INFO - 	at org.apache.sqoop.Sqoop.run(Sqoop.java:147)
[2022-06-07 06:11:24,441] {subprocess.py:92} INFO - 	at org.apache.hadoop.util.ToolRunner.run(ToolRunner.java:70)
[2022-06-07 06:11:24,442] {subprocess.py:92} INFO - 	at org.apache.sqoop.Sqoop.runSqoop(Sqoop.java:183)
[2022-06-07 06:11:24,443] {subprocess.py:92} INFO - 	at org.apache.sqoop.Sqoop.runTool(Sqoop.java:234)
[2022-06-07 06:11:24,444] {subprocess.py:92} INFO - 	at org.apache.sqoop.Sqoop.runTool(Sqoop.java:243)
[2022-06-07 06:11:24,444] {subprocess.py:92} INFO - 	at org.apache.sqoop.Sqoop.main(Sqoop.java:252)
[2022-06-07 06:11:24,445] {subprocess.py:92} INFO - 
[2022-06-07 06:11:24,448] {subprocess.py:92} INFO - Warning: /usr/lib/sqoop/bin/../../hbase does not exist! HBase imports will fail.
[2022-06-07 06:11:24,449] {subprocess.py:92} INFO - Please set $HBASE_HOME to the root of your HBase installation.
[2022-06-07 06:11:24,450] {subprocess.py:92} INFO - Warning: /usr/lib/sqoop/bin/../../hcatalog does not exist! HCatalog jobs will fail.
[2022-06-07 06:11:24,450] {subprocess.py:92} INFO - Please set $HCAT_HOME to the root of your HCatalog installation.
[2022-06-07 06:11:24,451] {subprocess.py:92} INFO - Warning: /usr/lib/sqoop/bin/../../accumulo does not exist! Accumulo imports will fail.
[2022-06-07 06:11:24,454] {subprocess.py:92} INFO - Please set $ACCUMULO_HOME to the root of your Accumulo installation.
[2022-06-07 06:11:24,455] {subprocess.py:92} INFO - Warning: /usr/lib/sqoop/bin/../../zookeeper does not exist! Accumulo imports will fail.
[2022-06-07 06:11:24,458] {subprocess.py:92} INFO - Please set $ZOOKEEPER_HOME to the root of your Zookeeper installation.
[2022-06-07 06:11:25,133] {subprocess.py:92} INFO - 22/06/07 06:11:25 INFO sqoop.Sqoop: Running Sqoop version: 1.4.7
[2022-06-07 06:11:25,216] {subprocess.py:92} INFO - 22/06/07 06:11:25 WARN tool.BaseSqoopTool: Setting your password on the command-line is insecure. Consider using -P instead.
[2022-06-07 06:11:25,318] {subprocess.py:92} INFO - 22/06/07 06:11:25 INFO manager.SqlManager: Using default fetchSize of 1000
[2022-06-07 06:11:25,320] {subprocess.py:92} INFO - 22/06/07 06:11:25 INFO tool.CodeGenTool: Beginning code generation
[2022-06-07 06:11:25,392] {subprocess.py:92} INFO - 22/06/07 06:11:25 ERROR manager.SqlManager: Error executing statement: org.postgresql.util.PSQLException: The connection attempt failed.
[2022-06-07 06:11:25,393] {subprocess.py:92} INFO - org.postgresql.util.PSQLException: The connection attempt failed.
[2022-06-07 06:11:25,394] {subprocess.py:92} INFO - 	at org.postgresql.core.v3.ConnectionFactoryImpl.openConnectionImpl(ConnectionFactoryImpl.java:315)
[2022-06-07 06:11:25,395] {subprocess.py:92} INFO - 	at org.postgresql.core.ConnectionFactory.openConnection(ConnectionFactory.java:51)
[2022-06-07 06:11:25,396] {subprocess.py:92} INFO - 	at org.postgresql.jdbc.PgConnection.<init>(PgConnection.java:223)
[2022-06-07 06:11:25,397] {subprocess.py:92} INFO - 	at org.postgresql.Driver.makeConnection(Driver.java:465)
[2022-06-07 06:11:25,398] {subprocess.py:92} INFO - 	at org.postgresql.Driver.connect(Driver.java:264)
[2022-06-07 06:11:25,398] {subprocess.py:92} INFO - 	at java.sql.DriverManager.getConnection(DriverManager.java:664)
[2022-06-07 06:11:25,400] {subprocess.py:92} INFO - 	at java.sql.DriverManager.getConnection(DriverManager.java:247)
[2022-06-07 06:11:25,401] {subprocess.py:92} INFO - 	at org.apache.sqoop.manager.SqlManager.makeConnection(SqlManager.java:904)
[2022-06-07 06:11:25,402] {subprocess.py:92} INFO - 	at org.apache.sqoop.manager.GenericJdbcManager.getConnection(GenericJdbcManager.java:59)
[2022-06-07 06:11:25,403] {subprocess.py:92} INFO - 	at org.apache.sqoop.manager.SqlManager.execute(SqlManager.java:763)
[2022-06-07 06:11:25,404] {subprocess.py:92} INFO - 	at org.apache.sqoop.manager.SqlManager.execute(SqlManager.java:786)
[2022-06-07 06:11:25,405] {subprocess.py:92} INFO - 	at org.apache.sqoop.manager.SqlManager.getColumnInfoForRawQuery(SqlManager.java:289)
[2022-06-07 06:11:25,405] {subprocess.py:92} INFO - 	at org.apache.sqoop.manager.SqlManager.getColumnTypesForRawQuery(SqlManager.java:260)
[2022-06-07 06:11:25,406] {subprocess.py:92} INFO - 	at org.apache.sqoop.manager.SqlManager.getColumnTypes(SqlManager.java:246)
[2022-06-07 06:11:25,407] {subprocess.py:92} INFO - 	at org.apache.sqoop.manager.ConnManager.getColumnTypes(ConnManager.java:327)
[2022-06-07 06:11:25,407] {subprocess.py:92} INFO - 	at org.apache.sqoop.orm.ClassWriter.getColumnTypes(ClassWriter.java:1872)
[2022-06-07 06:11:25,408] {subprocess.py:92} INFO - 	at org.apache.sqoop.orm.ClassWriter.generate(ClassWriter.java:1671)
[2022-06-07 06:11:25,409] {subprocess.py:92} INFO - 	at org.apache.sqoop.tool.CodeGenTool.generateORM(CodeGenTool.java:106)
[2022-06-07 06:11:25,410] {subprocess.py:92} INFO - 	at org.apache.sqoop.tool.ImportTool.importTable(ImportTool.java:501)
[2022-06-07 06:11:25,411] {subprocess.py:92} INFO - 	at org.apache.sqoop.tool.ImportTool.run(ImportTool.java:628)
[2022-06-07 06:11:25,413] {subprocess.py:92} INFO - 	at org.apache.sqoop.Sqoop.run(Sqoop.java:147)
[2022-06-07 06:11:25,415] {subprocess.py:92} INFO - 	at org.apache.hadoop.util.ToolRunner.run(ToolRunner.java:70)
[2022-06-07 06:11:25,417] {subprocess.py:92} INFO - 	at org.apache.sqoop.Sqoop.runSqoop(Sqoop.java:183)
[2022-06-07 06:11:25,422] {subprocess.py:92} INFO - 	at org.apache.sqoop.Sqoop.runTool(Sqoop.java:234)
[2022-06-07 06:11:25,423] {subprocess.py:92} INFO - 	at org.apache.sqoop.Sqoop.runTool(Sqoop.java:243)
[2022-06-07 06:11:25,424] {subprocess.py:92} INFO - 	at org.apache.sqoop.Sqoop.main(Sqoop.java:252)
[2022-06-07 06:11:25,424] {subprocess.py:92} INFO - Caused by: java.net.UnknownHostException: ***
[2022-06-07 06:11:25,425] {subprocess.py:92} INFO - 	at java.net.AbstractPlainSocketImpl.connect(AbstractPlainSocketImpl.java:184)
[2022-06-07 06:11:25,426] {subprocess.py:92} INFO - 	at java.net.SocksSocketImpl.connect(SocksSocketImpl.java:392)
[2022-06-07 06:11:25,427] {subprocess.py:92} INFO - 	at java.net.Socket.connect(Socket.java:589)
[2022-06-07 06:11:25,427] {subprocess.py:92} INFO - 	at org.postgresql.core.PGStream.createSocket(PGStream.java:231)
[2022-06-07 06:11:25,428] {subprocess.py:92} INFO - 	at org.postgresql.core.PGStream.<init>(PGStream.java:95)
[2022-06-07 06:11:25,429] {subprocess.py:92} INFO - 	at org.postgresql.core.v3.ConnectionFactoryImpl.tryConnect(ConnectionFactoryImpl.java:98)
[2022-06-07 06:11:25,430] {subprocess.py:92} INFO - 	at org.postgresql.core.v3.ConnectionFactoryImpl.openConnectionImpl(ConnectionFactoryImpl.java:213)
[2022-06-07 06:11:25,430] {subprocess.py:92} INFO - 	... 25 more
[2022-06-07 06:11:25,431] {subprocess.py:92} INFO - 22/06/07 06:11:25 ERROR tool.ImportTool: Import failed: java.io.IOException: No columns to generate for ClassWriter
[2022-06-07 06:11:25,432] {subprocess.py:92} INFO - 	at org.apache.sqoop.orm.ClassWriter.generate(ClassWriter.java:1677)
[2022-06-07 06:11:25,433] {subprocess.py:92} INFO - 	at org.apache.sqoop.tool.CodeGenTool.generateORM(CodeGenTool.java:106)
[2022-06-07 06:11:25,434] {subprocess.py:92} INFO - 	at org.apache.sqoop.tool.ImportTool.importTable(ImportTool.java:501)
[2022-06-07 06:11:25,435] {subprocess.py:92} INFO - 	at org.apache.sqoop.tool.ImportTool.run(ImportTool.java:628)
[2022-06-07 06:11:25,436] {subprocess.py:92} INFO - 	at org.apache.sqoop.Sqoop.run(Sqoop.java:147)
[2022-06-07 06:11:25,436] {subprocess.py:92} INFO - 	at org.apache.hadoop.util.ToolRunner.run(ToolRunner.java:70)
[2022-06-07 06:11:25,437] {subprocess.py:92} INFO - 	at org.apache.sqoop.Sqoop.runSqoop(Sqoop.java:183)
[2022-06-07 06:11:25,438] {subprocess.py:92} INFO - 	at org.apache.sqoop.Sqoop.runTool(Sqoop.java:234)
[2022-06-07 06:11:25,439] {subprocess.py:92} INFO - 	at org.apache.sqoop.Sqoop.runTool(Sqoop.java:243)
[2022-06-07 06:11:25,439] {subprocess.py:92} INFO - 	at org.apache.sqoop.Sqoop.main(Sqoop.java:252)
[2022-06-07 06:11:25,440] {subprocess.py:92} INFO - 
[2022-06-07 06:11:25,441] {subprocess.py:96} INFO - Command exited with return code 1
[2022-06-07 06:11:25,467] {taskinstance.py:1889} ERROR - Task failed with exception
Traceback (most recent call last):
  File "/home/airflow/.local/lib/python3.7/site-packages/airflow/operators/bash.py", line 195, in execute
    f'Bash command failed. The command returned a non-zero exit code {result.exit_code}.'
airflow.exceptions.AirflowException: Bash command failed. The command returned a non-zero exit code 1.
[2022-06-07 06:11:25,475] {taskinstance.py:1400} INFO - Marking task as UP_FOR_RETRY. dag_id=hands_on_test, task_id=import_sqoop, execution_date=20220606T000000, start_date=20220607T061118, end_date=20220607T061125
[2022-06-07 06:11:25,493] {standard_task_runner.py:97} ERROR - Failed to execute job 37 for task import_sqoop (Bash command failed. The command returned a non-zero exit code 1.; 6036)
[2022-06-07 06:11:25,526] {local_task_job.py:156} INFO - Task exited with return code 1
[2022-06-07 06:11:25,577] {local_task_job.py:273} INFO - 0 downstream tasks scheduled from follow-on schedule check
