[2022-06-06 11:35:55,230] {taskinstance.py:1159} INFO - Dependencies all met for <TaskInstance: hands_on_test.postgreq_data_quality_check manual__2022-06-06T11:35:51.895254+00:00 [queued]>
[2022-06-06 11:35:55,244] {taskinstance.py:1159} INFO - Dependencies all met for <TaskInstance: hands_on_test.postgreq_data_quality_check manual__2022-06-06T11:35:51.895254+00:00 [queued]>
[2022-06-06 11:35:55,245] {taskinstance.py:1356} INFO - 
--------------------------------------------------------------------------------
[2022-06-06 11:35:55,246] {taskinstance.py:1357} INFO - Starting attempt 1 of 2
[2022-06-06 11:35:55,246] {taskinstance.py:1358} INFO - 
--------------------------------------------------------------------------------
[2022-06-06 11:35:55,266] {taskinstance.py:1377} INFO - Executing <Task(PostgresDataQualityOperator): postgreq_data_quality_check> on 2022-06-06 11:35:51.895254+00:00
[2022-06-06 11:35:55,273] {standard_task_runner.py:52} INFO - Started process 2583 to run task
[2022-06-06 11:35:55,278] {standard_task_runner.py:79} INFO - Running: ['***', 'tasks', 'run', 'hands_on_test', 'postgreq_data_quality_check', 'manual__2022-06-06T11:35:51.895254+00:00', '--job-id', '27', '--raw', '--subdir', 'DAGS_FOLDER/dag.py', '--cfg-path', '/tmp/tmp_nivrcob', '--error-file', '/tmp/tmpvrt91j28']
[2022-06-06 11:35:55,280] {standard_task_runner.py:80} INFO - Job 27: Subtask postgreq_data_quality_check
[2022-06-06 11:35:55,360] {task_command.py:369} INFO - Running <TaskInstance: hands_on_test.postgreq_data_quality_check manual__2022-06-06T11:35:51.895254+00:00 [running]> on host 0c241499c9fe
[2022-06-06 11:35:55,455] {taskinstance.py:1571} INFO - Exporting the following env vars:
AIRFLOW_CTX_DAG_OWNER=pathairs
AIRFLOW_CTX_DAG_ID=hands_on_test
AIRFLOW_CTX_TASK_ID=postgreq_data_quality_check
AIRFLOW_CTX_EXECUTION_DATE=2022-06-06T11:35:51.895254+00:00
AIRFLOW_CTX_TRY_NUMBER=1
AIRFLOW_CTX_DAG_RUN_ID=manual__2022-06-06T11:35:51.895254+00:00
[2022-06-06 11:35:55,457] {data_quality.py:20} INFO - DataQualityOperator
[2022-06-06 11:35:55,472] {base.py:68} INFO - Using connection ID 'postgres_db' for task execution.
[2022-06-06 11:35:55,496] {base.py:68} INFO - Using connection ID 'postgres_db' for task execution.
[2022-06-06 11:35:55,510] {data_quality.py:32} WARNING - number of failed test case : 2
[2022-06-06 11:35:55,512] {data_quality.py:33} WARNING - ['SELECT COUNT(*) FROM order_detail;', 'SELECT COUNT(*) FROM restaurant_detail;']
[2022-06-06 11:35:55,512] {taskinstance.py:1889} ERROR - Task failed with exception
Traceback (most recent call last):
  File "/opt/airflow/plugins/operators/data_quality.py", line 34, in execute
    raise ValueError("Data quality check failed")
ValueError: Data quality check failed
[2022-06-06 11:35:55,526] {taskinstance.py:1400} INFO - Marking task as UP_FOR_RETRY. dag_id=hands_on_test, task_id=postgreq_data_quality_check, execution_date=20220606T113551, start_date=20220606T113555, end_date=20220606T113555
[2022-06-06 11:35:55,541] {standard_task_runner.py:97} ERROR - Failed to execute job 27 for task postgreq_data_quality_check (Data quality check failed; 2583)
[2022-06-06 11:35:55,571] {local_task_job.py:156} INFO - Task exited with return code 1
[2022-06-06 11:35:55,637] {local_task_job.py:273} INFO - 0 downstream tasks scheduled from follow-on schedule check
