[2022-06-06 11:06:46,889] {taskinstance.py:1159} INFO - Dependencies all met for <TaskInstance: hands_on_test.drop_restaurant_detail_table manual__2022-06-06T11:06:44.654504+00:00 [queued]>
[2022-06-06 11:06:46,908] {taskinstance.py:1159} INFO - Dependencies all met for <TaskInstance: hands_on_test.drop_restaurant_detail_table manual__2022-06-06T11:06:44.654504+00:00 [queued]>
[2022-06-06 11:06:46,909] {taskinstance.py:1356} INFO - 
--------------------------------------------------------------------------------
[2022-06-06 11:06:46,910] {taskinstance.py:1357} INFO - Starting attempt 1 of 2
[2022-06-06 11:06:46,911] {taskinstance.py:1358} INFO - 
--------------------------------------------------------------------------------
[2022-06-06 11:06:46,933] {taskinstance.py:1377} INFO - Executing <Task(PostgresOperator): drop_restaurant_detail_table> on 2022-06-06 11:06:44.654504+00:00
[2022-06-06 11:06:46,939] {standard_task_runner.py:52} INFO - Started process 458 to run task
[2022-06-06 11:06:46,945] {standard_task_runner.py:79} INFO - Running: ['***', 'tasks', 'run', 'hands_on_test', 'drop_restaurant_detail_table', 'manual__2022-06-06T11:06:44.654504+00:00', '--job-id', '9', '--raw', '--subdir', 'DAGS_FOLDER/dag.py', '--cfg-path', '/tmp/tmpxvcpu1bk', '--error-file', '/tmp/tmp3t6x1o65']
[2022-06-06 11:06:46,948] {standard_task_runner.py:80} INFO - Job 9: Subtask drop_restaurant_detail_table
[2022-06-06 11:06:47,098] {task_command.py:369} INFO - Running <TaskInstance: hands_on_test.drop_restaurant_detail_table manual__2022-06-06T11:06:44.654504+00:00 [running]> on host 0c241499c9fe
[2022-06-06 11:06:47,214] {taskinstance.py:1571} INFO - Exporting the following env vars:
AIRFLOW_CTX_DAG_OWNER=pathairs
AIRFLOW_CTX_DAG_ID=hands_on_test
AIRFLOW_CTX_TASK_ID=drop_restaurant_detail_table
AIRFLOW_CTX_EXECUTION_DATE=2022-06-06T11:06:44.654504+00:00
AIRFLOW_CTX_TRY_NUMBER=1
AIRFLOW_CTX_DAG_RUN_ID=manual__2022-06-06T11:06:44.654504+00:00
[2022-06-06 11:06:47,244] {taskinstance.py:1889} ERROR - Task failed with exception
Traceback (most recent call last):
  File "/home/airflow/.local/lib/python3.7/site-packages/airflow/providers/postgres/operators/postgres.py", line 92, in execute
    self.hook.run(self.sql, self.autocommit, parameters=self.parameters)
  File "/home/airflow/.local/lib/python3.7/site-packages/airflow/hooks/dbapi.py", line 181, in run
    with closing(self.get_conn()) as conn:
  File "/home/airflow/.local/lib/python3.7/site-packages/airflow/providers/postgres/hooks/postgres.py", line 86, in get_conn
    conn = deepcopy(self.connection or self.get_connection(conn_id))
  File "/home/airflow/.local/lib/python3.7/site-packages/airflow/hooks/base.py", line 67, in get_connection
    conn = Connection.get_connection_from_secrets(conn_id)
  File "/home/airflow/.local/lib/python3.7/site-packages/airflow/models/connection.py", line 430, in get_connection_from_secrets
    raise AirflowNotFoundException(f"The conn_id `{conn_id}` isn't defined")
airflow.exceptions.AirflowNotFoundException: The conn_id `postgres_db` isn't defined
[2022-06-06 11:06:47,250] {taskinstance.py:1400} INFO - Marking task as UP_FOR_RETRY. dag_id=hands_on_test, task_id=drop_restaurant_detail_table, execution_date=20220606T110644, start_date=20220606T110646, end_date=20220606T110647
[2022-06-06 11:06:47,413] {standard_task_runner.py:97} ERROR - Failed to execute job 9 for task drop_restaurant_detail_table (The conn_id `postgres_db` isn't defined; 458)
[2022-06-06 11:06:47,441] {local_task_job.py:156} INFO - Task exited with return code 1
[2022-06-06 11:06:47,678] {local_task_job.py:273} INFO - 0 downstream tasks scheduled from follow-on schedule check
