[2022-06-07 02:58:42,960] {taskinstance.py:1159} INFO - Dependencies all met for <TaskInstance: hands_on_test.drop_order_detail_table scheduled__2022-06-06T00:00:00+00:00 [queued]>
[2022-06-07 02:58:42,983] {taskinstance.py:1159} INFO - Dependencies all met for <TaskInstance: hands_on_test.drop_order_detail_table scheduled__2022-06-06T00:00:00+00:00 [queued]>
[2022-06-07 02:58:42,985] {taskinstance.py:1356} INFO - 
--------------------------------------------------------------------------------
[2022-06-07 02:58:42,986] {taskinstance.py:1357} INFO - Starting attempt 3 of 4
[2022-06-07 02:58:42,987] {taskinstance.py:1358} INFO - 
--------------------------------------------------------------------------------
[2022-06-07 02:58:43,037] {taskinstance.py:1377} INFO - Executing <Task(PostgresOperator): drop_order_detail_table> on 2022-06-06 00:00:00+00:00
[2022-06-07 02:58:43,053] {standard_task_runner.py:52} INFO - Started process 532 to run task
[2022-06-07 02:58:43,066] {standard_task_runner.py:79} INFO - Running: ['***', 'tasks', 'run', 'hands_on_test', 'drop_order_detail_table', 'scheduled__2022-06-06T00:00:00+00:00', '--job-id', '6', '--raw', '--subdir', 'DAGS_FOLDER/dag.py', '--cfg-path', '/tmp/tmpzhqeo2jt', '--error-file', '/tmp/tmpgx7wimrl']
[2022-06-07 02:58:43,069] {standard_task_runner.py:80} INFO - Job 6: Subtask drop_order_detail_table
[2022-06-07 02:58:43,166] {task_command.py:369} INFO - Running <TaskInstance: hands_on_test.drop_order_detail_table scheduled__2022-06-06T00:00:00+00:00 [running]> on host 90bb19738779
[2022-06-07 02:58:43,270] {taskinstance.py:1571} INFO - Exporting the following env vars:
AIRFLOW_CTX_DAG_OWNER=pathairs
AIRFLOW_CTX_DAG_ID=hands_on_test
AIRFLOW_CTX_TASK_ID=drop_order_detail_table
AIRFLOW_CTX_EXECUTION_DATE=2022-06-06T00:00:00+00:00
AIRFLOW_CTX_TRY_NUMBER=3
AIRFLOW_CTX_DAG_RUN_ID=scheduled__2022-06-06T00:00:00+00:00
[2022-06-07 02:58:43,284] {base.py:68} INFO - Using connection ID 'postgres_db' for task execution.
[2022-06-07 02:58:43,286] {taskinstance.py:1889} ERROR - Task failed with exception
Traceback (most recent call last):
  File "/home/airflow/.local/lib/python3.7/site-packages/airflow/providers/postgres/operators/postgres.py", line 92, in execute
    self.hook.run(self.sql, self.autocommit, parameters=self.parameters)
  File "/home/airflow/.local/lib/python3.7/site-packages/airflow/hooks/dbapi.py", line 181, in run
    with closing(self.get_conn()) as conn:
  File "/home/airflow/.local/lib/python3.7/site-packages/airflow/providers/postgres/hooks/postgres.py", line 113, in get_conn
    self.conn = psycopg2.connect(**conn_args)
  File "/home/airflow/.local/lib/python3.7/site-packages/psycopg2/__init__.py", line 122, in connect
    conn = _connect(dsn, connection_factory=connection_factory, **kwasync)
psycopg2.OperationalError: connection to server on socket "/var/run/postgresql/.s.PGSQL.5432" failed: No such file or directory
	Is the server running locally and accepting connections on that socket?

[2022-06-07 02:58:43,300] {taskinstance.py:1400} INFO - Marking task as UP_FOR_RETRY. dag_id=hands_on_test, task_id=drop_order_detail_table, execution_date=20220606T000000, start_date=20220607T025842, end_date=20220607T025843
[2022-06-07 02:58:43,319] {standard_task_runner.py:97} ERROR - Failed to execute job 6 for task drop_order_detail_table (connection to server on socket "/var/run/postgresql/.s.PGSQL.5432" failed: No such file or directory
	Is the server running locally and accepting connections on that socket?
; 532)
[2022-06-07 02:58:43,360] {local_task_job.py:156} INFO - Task exited with return code 1
[2022-06-07 02:58:43,429] {local_task_job.py:273} INFO - 0 downstream tasks scheduled from follow-on schedule check
