[2022-06-07 02:37:44,825] {taskinstance.py:1159} INFO - Dependencies all met for <TaskInstance: hands_on_test.drop_order_detail_table manual__2022-06-07T02:37:42.207499+00:00 [queued]>
[2022-06-07 02:37:44,846] {taskinstance.py:1159} INFO - Dependencies all met for <TaskInstance: hands_on_test.drop_order_detail_table manual__2022-06-07T02:37:42.207499+00:00 [queued]>
[2022-06-07 02:37:44,848] {taskinstance.py:1356} INFO - 
--------------------------------------------------------------------------------
[2022-06-07 02:37:44,848] {taskinstance.py:1357} INFO - Starting attempt 1 of 2
[2022-06-07 02:37:44,849] {taskinstance.py:1358} INFO - 
--------------------------------------------------------------------------------
[2022-06-07 02:37:44,879] {taskinstance.py:1377} INFO - Executing <Task(PostgresOperator): drop_order_detail_table> on 2022-06-07 02:37:42.207499+00:00
[2022-06-07 02:37:44,885] {standard_task_runner.py:52} INFO - Started process 295 to run task
[2022-06-07 02:37:44,892] {standard_task_runner.py:79} INFO - Running: ['***', 'tasks', 'run', 'hands_on_test', 'drop_order_detail_table', 'manual__2022-06-07T02:37:42.207499+00:00', '--job-id', '5', '--raw', '--subdir', 'DAGS_FOLDER/dag.py', '--cfg-path', '/tmp/tmpz18s8s34', '--error-file', '/tmp/tmp8g9qwtlm']
[2022-06-07 02:37:44,896] {standard_task_runner.py:80} INFO - Job 5: Subtask drop_order_detail_table
[2022-06-07 02:37:44,975] {task_command.py:369} INFO - Running <TaskInstance: hands_on_test.drop_order_detail_table manual__2022-06-07T02:37:42.207499+00:00 [running]> on host 078df8b61ea1
[2022-06-07 02:37:45,085] {taskinstance.py:1571} INFO - Exporting the following env vars:
AIRFLOW_CTX_DAG_OWNER=pathairs
AIRFLOW_CTX_DAG_ID=hands_on_test
AIRFLOW_CTX_TASK_ID=drop_order_detail_table
AIRFLOW_CTX_EXECUTION_DATE=2022-06-07T02:37:42.207499+00:00
AIRFLOW_CTX_TRY_NUMBER=1
AIRFLOW_CTX_DAG_RUN_ID=manual__2022-06-07T02:37:42.207499+00:00
[2022-06-07 02:37:45,114] {taskinstance.py:1889} ERROR - Task failed with exception
Traceback (most recent call last):
  File "/home/airflow/.local/lib/python3.7/site-packages/airflow/providers/postgres/operators/postgres.py", line 92, in execute
    self.hook.run(self.sql, self.autocommit, parameters=self.parameters)
  File "/home/airflow/.local/lib/python3.7/site-packages/airflow/hooks/dbapi.py", line 181, in run
    with closing(self.get_conn()) as conn:
  File "/home/airflow/.local/lib/python3.7/site-packages/airflow/providers/postgres/hooks/postgres.py", line 86, in get_conn
    conn = deepcopy(self.connection or self.get_connection(conn_id))
  File "/home/airflow/.local/lib/python3.7/site-packages/airflow/hooks/base.py", line 67, in get_connection
    conn = Connection.get_connection_from_secrets(conn_id)
  File "/home/airflow/.local/lib/python3.7/site-packages/airflow/models/connection.py", line 430, in get_connection_from_secrets
    raise AirflowNotFoundException(f"The conn_id `{conn_id}` isn't defined")
airflow.exceptions.AirflowNotFoundException: The conn_id `postgres_db` isn't defined
[2022-06-07 02:37:45,121] {taskinstance.py:1400} INFO - Marking task as UP_FOR_RETRY. dag_id=hands_on_test, task_id=drop_order_detail_table, execution_date=20220607T023742, start_date=20220607T023744, end_date=20220607T023745
[2022-06-07 02:37:45,135] {standard_task_runner.py:97} ERROR - Failed to execute job 5 for task drop_order_detail_table (The conn_id `postgres_db` isn't defined; 295)
[2022-06-07 02:37:45,185] {local_task_job.py:156} INFO - Task exited with return code 1
[2022-06-07 02:37:45,246] {local_task_job.py:273} INFO - 0 downstream tasks scheduled from follow-on schedule check
