[2022-06-08 04:54:07,066] {taskinstance.py:1159} INFO - Dependencies all met for <TaskInstance: hands_on_test.import_sqoop manual__2022-06-08T02:39:54.959518+00:00 [queued]>
[2022-06-08 04:54:07,082] {taskinstance.py:1159} INFO - Dependencies all met for <TaskInstance: hands_on_test.import_sqoop manual__2022-06-08T02:39:54.959518+00:00 [queued]>
[2022-06-08 04:54:07,083] {taskinstance.py:1356} INFO - 
--------------------------------------------------------------------------------
[2022-06-08 04:54:07,084] {taskinstance.py:1357} INFO - Starting attempt 10 of 11
[2022-06-08 04:54:07,085] {taskinstance.py:1358} INFO - 
--------------------------------------------------------------------------------
[2022-06-08 04:54:07,109] {taskinstance.py:1377} INFO - Executing <Task(BashOperator): import_sqoop> on 2022-06-08 02:39:54.959518+00:00
[2022-06-08 04:54:07,120] {standard_task_runner.py:52} INFO - Started process 9358 to run task
[2022-06-08 04:54:07,125] {standard_task_runner.py:79} INFO - Running: ['***', 'tasks', 'run', 'hands_on_test', 'import_sqoop', 'manual__2022-06-08T02:39:54.959518+00:00', '--job-id', '118', '--raw', '--subdir', 'DAGS_FOLDER/dag.py', '--cfg-path', '/tmp/tmpxq98k3bm', '--error-file', '/tmp/tmpgscchkuo']
[2022-06-08 04:54:07,127] {standard_task_runner.py:80} INFO - Job 118: Subtask import_sqoop
[2022-06-08 04:54:07,206] {task_command.py:369} INFO - Running <TaskInstance: hands_on_test.import_sqoop manual__2022-06-08T02:39:54.959518+00:00 [running]> on host b79bd65fcc57
[2022-06-08 04:54:07,330] {taskinstance.py:1571} INFO - Exporting the following env vars:
AIRFLOW_CTX_DAG_OWNER=***
AIRFLOW_CTX_DAG_ID=hands_on_test
AIRFLOW_CTX_TASK_ID=import_sqoop
AIRFLOW_CTX_EXECUTION_DATE=2022-06-08T02:39:54.959518+00:00
AIRFLOW_CTX_TRY_NUMBER=10
AIRFLOW_CTX_DAG_RUN_ID=manual__2022-06-08T02:39:54.959518+00:00
[2022-06-08 04:54:07,334] {subprocess.py:62} INFO - Tmp dir root location: 
 /tmp
[2022-06-08 04:54:07,336] {subprocess.py:74} INFO - Running command: ['bash', '-c', 'docker exec hive-server bash /opt/sqoop/import_sqoop.sh ']
[2022-06-08 04:54:07,355] {subprocess.py:85} INFO - Output:
[2022-06-08 04:54:09,130] {subprocess.py:92} INFO - 22/06/08 04:54:09 INFO fs.TrashPolicyDefault: Namenode trash configuration: Deletion interval = 0 minutes, Emptier interval = 0 minutes.
[2022-06-08 04:54:09,137] {subprocess.py:92} INFO - Deleted /user/sqoop
[2022-06-08 04:54:11,638] {subprocess.py:92} INFO - Warning: /usr/lib/sqoop/bin/../../hbase does not exist! HBase imports will fail.
[2022-06-08 04:54:11,640] {subprocess.py:92} INFO - Please set $HBASE_HOME to the root of your HBase installation.
[2022-06-08 04:54:11,642] {subprocess.py:92} INFO - Warning: /usr/lib/sqoop/bin/../../hcatalog does not exist! HCatalog jobs will fail.
[2022-06-08 04:54:11,644] {subprocess.py:92} INFO - Please set $HCAT_HOME to the root of your HCatalog installation.
[2022-06-08 04:54:11,645] {subprocess.py:92} INFO - Warning: /usr/lib/sqoop/bin/../../accumulo does not exist! Accumulo imports will fail.
[2022-06-08 04:54:11,646] {subprocess.py:92} INFO - Please set $ACCUMULO_HOME to the root of your Accumulo installation.
[2022-06-08 04:54:11,647] {subprocess.py:92} INFO - Warning: /usr/lib/sqoop/bin/../../zookeeper does not exist! Accumulo imports will fail.
[2022-06-08 04:54:11,649] {subprocess.py:92} INFO - Please set $ZOOKEEPER_HOME to the root of your Zookeeper installation.
[2022-06-08 04:54:12,228] {subprocess.py:92} INFO - 22/06/08 04:54:12 INFO sqoop.Sqoop: Running Sqoop version: 1.4.7
[2022-06-08 04:54:12,313] {subprocess.py:92} INFO - 22/06/08 04:54:12 WARN tool.BaseSqoopTool: Setting your password on the command-line is insecure. Consider using -P instead.
[2022-06-08 04:54:12,316] {subprocess.py:92} INFO - 22/06/08 04:54:12 ERROR tool.BaseSqoopTool: Error parsing arguments for import:
[2022-06-08 04:54:12,318] {subprocess.py:92} INFO - 22/06/08 04:54:12 ERROR tool.BaseSqoopTool: Unrecognized argument:
[2022-06-08 04:54:12,319] {subprocess.py:92} INFO - 
[2022-06-08 04:54:12,320] {subprocess.py:92} INFO - Try --help for usage instructions.
[2022-06-08 04:54:12,350] {subprocess.py:96} INFO - Command exited with return code 1
[2022-06-08 04:54:12,372] {taskinstance.py:1889} ERROR - Task failed with exception
Traceback (most recent call last):
  File "/home/airflow/.local/lib/python3.7/site-packages/airflow/operators/bash.py", line 195, in execute
    f'Bash command failed. The command returned a non-zero exit code {result.exit_code}.'
airflow.exceptions.AirflowException: Bash command failed. The command returned a non-zero exit code 1.
[2022-06-08 04:54:12,377] {taskinstance.py:1400} INFO - Marking task as UP_FOR_RETRY. dag_id=hands_on_test, task_id=import_sqoop, execution_date=20220608T023954, start_date=20220608T045407, end_date=20220608T045412
[2022-06-08 04:54:12,393] {standard_task_runner.py:97} ERROR - Failed to execute job 118 for task import_sqoop (Bash command failed. The command returned a non-zero exit code 1.; 9358)
[2022-06-08 04:54:12,443] {local_task_job.py:156} INFO - Task exited with return code 1
[2022-06-08 04:54:12,500] {local_task_job.py:273} INFO - 0 downstream tasks scheduled from follow-on schedule check
