[2022-06-10 06:57:44,912] {taskinstance.py:1159} INFO - Dependencies all met for <TaskInstance: hands_on_test.copy_order_data manual__2022-06-10T06:57:39.204816+00:00 [queued]>
[2022-06-10 06:57:44,946] {taskinstance.py:1159} INFO - Dependencies all met for <TaskInstance: hands_on_test.copy_order_data manual__2022-06-10T06:57:39.204816+00:00 [queued]>
[2022-06-10 06:57:44,947] {taskinstance.py:1356} INFO - 
--------------------------------------------------------------------------------
[2022-06-10 06:57:44,948] {taskinstance.py:1357} INFO - Starting attempt 1 of 2
[2022-06-10 06:57:44,949] {taskinstance.py:1358} INFO - 
--------------------------------------------------------------------------------
[2022-06-10 06:57:44,979] {taskinstance.py:1377} INFO - Executing <Task(MySqlOperator): copy_order_data> on 2022-06-10 06:57:39.204816+00:00
[2022-06-10 06:57:44,985] {standard_task_runner.py:52} INFO - Started process 388 to run task
[2022-06-10 06:57:44,999] {standard_task_runner.py:79} INFO - Running: ['***', 'tasks', 'run', 'hands_on_test', 'copy_order_data', 'manual__2022-06-10T06:57:39.204816+00:00', '--job-id', '14', '--raw', '--subdir', 'DAGS_FOLDER/dag.py', '--cfg-path', '/tmp/tmpz_2pctr_', '--error-file', '/tmp/tmpa6nssp1k']
[2022-06-10 06:57:45,002] {standard_task_runner.py:80} INFO - Job 14: Subtask copy_order_data
[2022-06-10 06:57:45,160] {task_command.py:369} INFO - Running <TaskInstance: hands_on_test.copy_order_data manual__2022-06-10T06:57:39.204816+00:00 [running]> on host a0fd966c00bf
[2022-06-10 06:57:45,476] {taskinstance.py:1571} INFO - Exporting the following env vars:
AIRFLOW_CTX_DAG_OWNER=***
AIRFLOW_CTX_DAG_ID=hands_on_test
AIRFLOW_CTX_TASK_ID=copy_order_data
AIRFLOW_CTX_EXECUTION_DATE=2022-06-10T06:57:39.204816+00:00
AIRFLOW_CTX_TRY_NUMBER=1
AIRFLOW_CTX_DAG_RUN_ID=manual__2022-06-10T06:57:39.204816+00:00
[2022-06-10 06:57:45,480] {mysql.py:82} INFO - Executing: 
LOAD DATA INFILE '/var/lib/mysql/Orders.csv' INTO TABLE orders FIELDS TERMINATED BY ','
IGNORE 1 ROWS;
[2022-06-10 06:57:45,525] {base.py:68} INFO - Using connection ID 'mysql_db' for task execution.
[2022-06-10 06:57:45,686] {dbapi.py:208} INFO - Running statement: 
LOAD DATA INFILE '/var/lib/mysql/Orders.csv' INTO TABLE orders FIELDS TERMINATED BY ','
IGNORE 1 ROWS;, parameters: None
[2022-06-10 06:57:45,691] {taskinstance.py:1889} ERROR - Task failed with exception
Traceback (most recent call last):
  File "/home/airflow/.local/lib/python3.7/site-packages/airflow/providers/mysql/operators/mysql.py", line 84, in execute
    hook.run(self.sql, autocommit=self.autocommit, parameters=self.parameters)
  File "/home/airflow/.local/lib/python3.7/site-packages/airflow/hooks/dbapi.py", line 188, in run
    self._run_command(cur, sql_statement, parameters)
  File "/home/airflow/.local/lib/python3.7/site-packages/airflow/hooks/dbapi.py", line 212, in _run_command
    cur.execute(sql_statement)
  File "/home/airflow/.local/lib/python3.7/site-packages/MySQLdb/cursors.py", line 206, in execute
    res = self._query(query)
  File "/home/airflow/.local/lib/python3.7/site-packages/MySQLdb/cursors.py", line 319, in _query
    db.query(q)
  File "/home/airflow/.local/lib/python3.7/site-packages/MySQLdb/connections.py", line 254, in query
    _mysql.connection.query(self, query)
MySQLdb._exceptions.OperationalError: (1045, "Access denied for user '***'@'%' (using password: YES)")
[2022-06-10 06:57:45,722] {taskinstance.py:1400} INFO - Marking task as UP_FOR_RETRY. dag_id=hands_on_test, task_id=copy_order_data, execution_date=20220610T065739, start_date=20220610T065744, end_date=20220610T065745
[2022-06-10 06:57:45,805] {standard_task_runner.py:97} ERROR - Failed to execute job 14 for task copy_order_data ((1045, "Access denied for user '***'@'%' (using password: YES)"); 388)
[2022-06-10 06:57:45,869] {local_task_job.py:156} INFO - Task exited with return code 1
[2022-06-10 06:57:46,033] {local_task_job.py:273} INFO - 0 downstream tasks scheduled from follow-on schedule check
