[2022-06-08 06:24:39,326] {taskinstance.py:1159} INFO - Dependencies all met for <TaskInstance: hands_on_test.postgreq_data_quality_check manual__2022-06-08T06:24:27.287026+00:00 [queued]>
[2022-06-08 06:24:39,343] {taskinstance.py:1159} INFO - Dependencies all met for <TaskInstance: hands_on_test.postgreq_data_quality_check manual__2022-06-08T06:24:27.287026+00:00 [queued]>
[2022-06-08 06:24:39,344] {taskinstance.py:1356} INFO - 
--------------------------------------------------------------------------------
[2022-06-08 06:24:39,344] {taskinstance.py:1357} INFO - Starting attempt 1 of 2
[2022-06-08 06:24:39,345] {taskinstance.py:1358} INFO - 
--------------------------------------------------------------------------------
[2022-06-08 06:24:39,368] {taskinstance.py:1377} INFO - Executing <Task(PostgresDataQualityOperator): postgreq_data_quality_check> on 2022-06-08 06:24:27.287026+00:00
[2022-06-08 06:24:39,376] {standard_task_runner.py:52} INFO - Started process 15344 to run task
[2022-06-08 06:24:39,382] {standard_task_runner.py:79} INFO - Running: ['***', 'tasks', 'run', 'hands_on_test', 'postgreq_data_quality_check', 'manual__2022-06-08T06:24:27.287026+00:00', '--job-id', '194', '--raw', '--subdir', 'DAGS_FOLDER/dag.py', '--cfg-path', '/tmp/tmpda4za9qu', '--error-file', '/tmp/tmpjxszmxkp']
[2022-06-08 06:24:39,384] {standard_task_runner.py:80} INFO - Job 194: Subtask postgreq_data_quality_check
[2022-06-08 06:24:39,458] {task_command.py:369} INFO - Running <TaskInstance: hands_on_test.postgreq_data_quality_check manual__2022-06-08T06:24:27.287026+00:00 [running]> on host b79bd65fcc57
[2022-06-08 06:24:39,561] {taskinstance.py:1571} INFO - Exporting the following env vars:
AIRFLOW_CTX_DAG_OWNER=***
AIRFLOW_CTX_DAG_ID=hands_on_test
AIRFLOW_CTX_TASK_ID=postgreq_data_quality_check
AIRFLOW_CTX_EXECUTION_DATE=2022-06-08T06:24:27.287026+00:00
AIRFLOW_CTX_TRY_NUMBER=1
AIRFLOW_CTX_DAG_RUN_ID=manual__2022-06-08T06:24:27.287026+00:00
[2022-06-08 06:24:39,563] {data_quality.py:20} INFO - DataQualityOperator
[2022-06-08 06:24:39,582] {base.py:68} INFO - Using connection ID 'postgres_db' for task execution.
[2022-06-08 06:24:39,646] {base.py:68} INFO - Using connection ID 'postgres_db' for task execution.
[2022-06-08 06:24:39,672] {base.py:68} INFO - Using connection ID 'postgres_db' for task execution.
[2022-06-08 06:24:39,690] {data_quality.py:32} WARNING - number of failed test case : 1
[2022-06-08 06:24:39,691] {data_quality.py:33} WARNING - ['SELECT COUNT(*) FROM orders;']
[2022-06-08 06:24:39,692] {taskinstance.py:1889} ERROR - Task failed with exception
Traceback (most recent call last):
  File "/opt/airflow/plugins/operators/data_quality.py", line 34, in execute
    raise ValueError("Data quality check failed")
ValueError: Data quality check failed
[2022-06-08 06:24:39,706] {taskinstance.py:1400} INFO - Marking task as UP_FOR_RETRY. dag_id=hands_on_test, task_id=postgreq_data_quality_check, execution_date=20220608T062427, start_date=20220608T062439, end_date=20220608T062439
[2022-06-08 06:24:39,725] {standard_task_runner.py:97} ERROR - Failed to execute job 194 for task postgreq_data_quality_check (Data quality check failed; 15344)
[2022-06-08 06:24:39,756] {local_task_job.py:156} INFO - Task exited with return code 1
[2022-06-08 06:24:39,852] {local_task_job.py:273} INFO - 0 downstream tasks scheduled from follow-on schedule check
