[2022-06-08 06:20:11,572] {taskinstance.py:1159} INFO - Dependencies all met for <TaskInstance: hands_on_test.drop_order_table manual__2022-06-08T06:18:40.397380+00:00 [queued]>
[2022-06-08 06:20:11,586] {taskinstance.py:1159} INFO - Dependencies all met for <TaskInstance: hands_on_test.drop_order_table manual__2022-06-08T06:18:40.397380+00:00 [queued]>
[2022-06-08 06:20:11,587] {taskinstance.py:1356} INFO - 
--------------------------------------------------------------------------------
[2022-06-08 06:20:11,588] {taskinstance.py:1357} INFO - Starting attempt 3 of 4
[2022-06-08 06:20:11,589] {taskinstance.py:1358} INFO - 
--------------------------------------------------------------------------------
[2022-06-08 06:20:11,611] {taskinstance.py:1377} INFO - Executing <Task(PostgresOperator): drop_order_table> on 2022-06-08 06:18:40.397380+00:00
[2022-06-08 06:20:11,617] {standard_task_runner.py:52} INFO - Started process 15046 to run task
[2022-06-08 06:20:11,623] {standard_task_runner.py:79} INFO - Running: ['***', 'tasks', 'run', 'hands_on_test', 'drop_order_table', 'manual__2022-06-08T06:18:40.397380+00:00', '--job-id', '177', '--raw', '--subdir', 'DAGS_FOLDER/dag.py', '--cfg-path', '/tmp/tmp8gzu67x3', '--error-file', '/tmp/tmpnh3754wl']
[2022-06-08 06:20:11,626] {standard_task_runner.py:80} INFO - Job 177: Subtask drop_order_table
[2022-06-08 06:20:11,704] {task_command.py:369} INFO - Running <TaskInstance: hands_on_test.drop_order_table manual__2022-06-08T06:18:40.397380+00:00 [running]> on host b79bd65fcc57
[2022-06-08 06:20:11,808] {taskinstance.py:1571} INFO - Exporting the following env vars:
AIRFLOW_CTX_DAG_OWNER=***
AIRFLOW_CTX_DAG_ID=hands_on_test
AIRFLOW_CTX_TASK_ID=drop_order_table
AIRFLOW_CTX_EXECUTION_DATE=2022-06-08T06:18:40.397380+00:00
AIRFLOW_CTX_TRY_NUMBER=3
AIRFLOW_CTX_DAG_RUN_ID=manual__2022-06-08T06:18:40.397380+00:00
[2022-06-08 06:20:11,822] {base.py:68} INFO - Using connection ID 'postgres_db' for task execution.
[2022-06-08 06:20:11,840] {dbapi.py:208} INFO - Running statement: 
DROP TABLE IF EXISTS order;, parameters: None
[2022-06-08 06:20:11,843] {taskinstance.py:1889} ERROR - Task failed with exception
Traceback (most recent call last):
  File "/home/airflow/.local/lib/python3.7/site-packages/airflow/providers/postgres/operators/postgres.py", line 92, in execute
    self.hook.run(self.sql, self.autocommit, parameters=self.parameters)
  File "/home/airflow/.local/lib/python3.7/site-packages/airflow/hooks/dbapi.py", line 188, in run
    self._run_command(cur, sql_statement, parameters)
  File "/home/airflow/.local/lib/python3.7/site-packages/airflow/hooks/dbapi.py", line 212, in _run_command
    cur.execute(sql_statement)
psycopg2.errors.SyntaxError: syntax error at or near "order"
LINE 2: DROP TABLE IF EXISTS order;
                             ^

[2022-06-08 06:20:11,856] {taskinstance.py:1400} INFO - Marking task as UP_FOR_RETRY. dag_id=hands_on_test, task_id=drop_order_table, execution_date=20220608T061840, start_date=20220608T062011, end_date=20220608T062011
[2022-06-08 06:20:11,871] {standard_task_runner.py:97} ERROR - Failed to execute job 177 for task drop_order_table (syntax error at or near "order"
LINE 2: DROP TABLE IF EXISTS order;
                             ^
; 15046)
[2022-06-08 06:20:11,917] {local_task_job.py:156} INFO - Task exited with return code 1
[2022-06-08 06:20:12,013] {local_task_job.py:273} INFO - 0 downstream tasks scheduled from follow-on schedule check
